Workbook
Name Slicer_Department_Name: #N/A
Name Slicer_Year: #N/A

Sheet Admissions
A1: Admission_ID | B1: Patient_ID | C1: Patient_Name | D1: Gender | E1: DOB | F1: Department | G1: Doctor_Name | H1: Admission_Date | I1: Discharge_Date | J1: LOS | K1: Total_Cost | L1: Readmitted | M1: Diagnosis_Code | N1: Insurance_Type | O1: Date Validity | P1: Cost Per Day | Q1: Cost Outlier | R1: Day Name | S1: Day Type | T1: Cost_Benchmark | U1: Above Benchmark | V1: Patients Age | W1: Age-group
A2: 14056 | B2: 3896 | C2: Helen Mutua | D2: Female | E2: 34733 | F2: Emergency | G2: Dr. Otieno | H2: 45206 | I2: 45208 | J2: 2 | K2: 4029 | L2: No | M2: S72 | N2: Public | O2: Valid | P2: 2014.5 | Q2: Ok | R2: Sat | S2: Weekend | T2: =VLOOKUP(Admissions[[#This Row],[Department]],Departments!A:E,5,FALSE) -> 5500 | U2: =IF(K2>T2,"Above Benchmark","Within Benchmark") -> Within Benchmark | V2: =INT(YEARFRAC(E2,TODAY())) -> 31 | W2: =_xlfn.IFS(Admissions[[#This Row],[Patients Age]]<18,"Paediatric",V2<40,"Young Adult",V2<65,"Adult",TRUE,"Senior") -> Young Adult
A3: 13383 | B3: 4990 | C3: Henry Adhiambo | D3: Female | E3: 26879 | F3: Oncology | G3: Dr. Osei | H3: 45327 | I3: 45335 | J3: 8 | K3: 28558 | L3: No | M3: C50 | N3: Uninsured | O3: Valid | P3: 3569.75 | Q3: Ok | R3: Mon | S3: Weekday | T3: =VLOOKUP(Admissions[[#This Row],[Department]],Departments!A:E,5,FALSE) -> 12000 | U3: =IF(K3>T3,"Above Benchmark","Within Benchmark") -> Above Benchmark | V3: =INT(YEARFRAC(E3,TODAY())) -> 52 | W3: =_xlfn.IFS(Admissions[[#This Row],[Patients Age]]<18,"Paediatric",V3<40,"Young Adult",V3<65,"Adult",TRUE,"Senior") -> Adult
A4: 11243 | B4: 3768 | C4: Mark Mwangi | D4: Female | E4: 11931 | F4: Surgery | G4: Dr. Muthoni | H4: 45246 | I4: 45252 | J4: 6 | K4: 17181 | L4: No | M4: C34 | N4: Public | O4: Valid | P4: 2863.5 | Q4: Ok | R4: Thu | S4: Weekday | T4: =VLOOKUP(Admissions[[#This Row],[Department]],Departments!A:E,5,FALSE) -> 9000 | U4: =IF(K4>T4,"Above Benchmark","Within Benchmark") -> Above Benchmark | V4: =INT(YEARFRAC(E4,TODAY())) -> 93 | W4: =_xlfn.IFS(Admissions[[#This Row],[Patients Age]]<18,"Paediatric",V4<40,"Young Adult",V4<65,"Adult",TRUE,"Senior") -> Senior
A5: 12638 | B5: 3202 | C5: Mark Githinji | D5: Female | E5: 41057 | F5: Pediatrics | G5: Dr. Korir | H5: 45305 | I5: 45308 | J5: 3 | K5: 3846 | L5: No | M5: Z38 | N5: Private | O5: Valid | P5: 1282 | Q5: Ok | R5: Sun | S5: Weekend | T5: =VLOOKUP(Admissions[[#This Row],[Department]],Departments!A:E,5,FALSE) -> 4500 | U5: =IF(K5>T5,"Above Benchmark","Within Benchmark") -> Within Benchmark | V5: =INT(YEARFRAC(E5,TODAY())) -> 14 | W5: =_xlfn.IFS(Admissions[[#This Row],[Patients Age]]<18,"Paediatric",V5<40,"Young Adult",V5<65,"Adult",TRUE,"Senior") -> Paediatric
A6: 10633 | B6: 5267 | C6: Helen Njenga | D6: Female | E6: 12772 | F6: Cardiology | G6: Dr. Patel | H6: 45606 | I6: 45612 | J6: 6 | K6: 13125 | L6: No | M6: I10 | N6: Private | O6: Valid | P6: 2187.5 | Q6: Ok | R6: Sun | S6: Weekend | T6: =VLOOKUP(Admissions[[#This Row],[Department]],Departments!A:E,5,FALSE) -> 8500 | U6: =IF(K6>T6,"Above Benchmark","Within Benchmark") -> Above Benchmark | V6: =INT(YEARFRAC(E6,TODAY())) -> 91 | W6: =_xlfn.IFS(Admissions[[#This Row],[Patients Age]]<18,"Paediatric",V6<40,"Young Adult",V6<65,"Adult",TRUE,"Senior") -> Senior
A7: 12614 | B7: 4502 | C7: Aisha Wairimu | D7: Female | E7: 11912 | F7: Surgery | G7: Dr. Chen | H7: 45153 | I7: 45163 | J7: 10 | K7: 21812 | L7: No | M7: S72 | N7: Public | O7: Valid | P7: 2181.2 | Q7: Ok | R7: Tue | S7: Weekday | T7: =VLOOKUP(Admissions[[#This Row],[Department]],Departments!A:E,5,FALSE) -> 9000 | U7: =IF(K7>T7,"Above Benchmark","Within Benchmark") -> Above Benchmark | V7: =INT(YEARFRAC(E7,TODAY())) -> 93 | W7: =_xlfn.IFS(Admissions[[#This Row],[Patients Age]]<18,"Paediatric",V7<40,"Young Adult",V7<65,"Adult",TRUE,"Senior") -> Senior
A8: 12708 | B8: 4444 | C8: Anthony Njenga | D8: Female | E8: 28771 | F8: Neurology | G8: Dr. Andersen | H8: 45624 | I8: 45632 | J8: 8 | K8: 14181 | L8: No | M8: G20 | N8: Private | O8: Valid | P8: 1772.625 | Q8: Ok | R8: Thu | S8: Weekday | T8: =VLOOKUP(Admissions[[#This Row],[Department]],Departments!A:E,5,FALSE) -> 7200 | U8: =IF(K8>T8,"Above Benchmark","Within Benchmark") -> Above Benchmark | V8: =INT(YEARFRAC(E8,TODAY())) -> 47 | W8: =_xlfn.IFS(Admissions[[#This Row],[Patients Age]]<18,"Paediatric",V8<40,"Young Adult",V8<65,"Adult",TRUE,"Senior") -> Adult
A9: 11263 | B9: 5471 | C9: Paul Njenga | D9: Female | E9: 18150 | F9: Oncology | G9: Dr. Osei | H9: 45522 | I9: 45534 | J9: 12 | K9: 0 | L9: No | M9: C50 | N9: Public | O9: Valid | P9: 0 | Q9: Flag | R9: Sun | S9: Weekend | T9: =VLOOKUP(Admissions[[#This Row],[Department]],Departments!A:E,5,FALSE) -> 12000 | U9: =IF(K9>T9,"Above Benchmark","Within Benchmark") -> Within Benchmark | V9: =INT(YEARFRAC(E9,TODAY())) -> 76 | W9: =_xlfn.IFS(Admissions[[#This Row],[Patients Age]]<18,"Paediatric",V9<40,"Young Adult",V9<65,"Adult",TRUE,"Senior") -> Senior
A10: 12099 | B10: 3743 | C10: William Mugo | D10: Female | E10: 43879 | F10: Pediatrics | G10: Dr. Korir | H10: 44930 | I10: 44933 | J10: 3 | K10: 2764 | L10: No | M10: A09 | N10: Private | O10: Valid | P10: 921.3333 | Q10: Ok | R10: Wed | S10: Weekday | T10: =VLOOKUP(Admissions[[#This Row],[Department]],Departments!A:E,5,FALSE) -> 4500 | U10: =IF(K10>T10,"Above Benchmark","Within Benchmark") -> Within Benchmark | V10: =INT(YEARFRAC(E10,TODAY())) -> 6 | W10: =_xlfn.IFS(Admissions[[#This Row],[Patients Age]]<18,"Paediatric",V10<40,"Young Adult",V10<65,"Adult",TRUE,"Senior") -> Paediatric
A11: 11552 | B11: 5884 | C11: Anthony Oduya | D11: Female | E11: 17985 | F11: Emergency | G11: Dr. Hassan | H11: 45576 | I11: 45579 | J11: 3 | K11: 7055 | L11: No | M11: R51 | N11: Public | O11: Valid | P11: 2351.6667 | Q11: Ok | R11: Fri | S11: Weekday | T11: =VLOOKUP(Admissions[[#This Row],[Department]],Departments!A:E,5,FALSE) -> 5500 | U11: =IF(K11>T11,"Above Benchmark","Within Benchmark") -> Above Benchmark | V11: =INT(YEARFRAC(E11,TODAY())) -> 77 | W11: =_xlfn.IFS(Admissions[[#This Row],[Patients Age]]<18,"Paediatric",V11<40,"Young Adult",V11<65,"Adult",TRUE,"Senior") -> Senior
A12: 11101 | B12: 3817 | C12: John Odhiambo | D12: Female | E12: 18083 | F12: Orthopedics | G12: Dr. Svensson | H12: 44939 | I12: 44947 | J12: 8 | K12: 10789 | L12: No | M12: M54 | N12: Private | O12: Valid | P12: 1348.625 | Q12: Ok | R12: Fri | S12: Weekday | T12: =VLOOKUP(Admissions[[#This Row],[Department]],Departments!A:E,5,FALSE) -> 6800 | U12: =IF(K12>T12,"Above Benchmark","Within Benchmark") -> Above Benchmark | V12: =INT(YEARFRAC(E12,TODAY())) -> 77 | W12: =_xlfn.IFS(Admissions[[#This Row],[Patients Age]]<18,"Paediatric",V12<40,"Young Adult",V12<65,"Adult",TRUE,"Senior") -> Senior
A13: 13829 | B13: 6591 | C13: Betty Achieng | D13: Female | E13: 11422 | F13: Emergency | G13: Dr. Hassan | H13: 45097 | I13: 45100 | J13: 3 | K13: 5765 | L13: No | M13: DX202 | N13: Private | O13: Valid | P13: 1921.6667 | Q13: Ok | R13: Tue | S13: Weekday | T13: =VLOOKUP(Admissions[[#This Row],[Department]],Departments!A:E,5,FALSE) -> 5500 | U13: =IF(K13>T13,"Above Benchmark","Within Benchmark") -> Above Benchmark | V13: =INT(YEARFRAC(E13,TODAY())) -> 95 | W13: =_xlfn.IFS(Admissions[[#This Row],[Patients Age]]<18,"Paediatric",V13<40,"Young Adult",V13<65,"Adult",TRUE,"Senior") -> Senior
... A37: 15153 | B37: 6581 | C37: Jessica Mwangi | D37: Female | E37: 27427 | F37: Orthopedics | G37: Dr. Svensson | H37: 45590 | I37: 45597 | J37: 7 | K37: 9025 | L37: No | M37: S72 | N37: Public | O37: Valid | P37: 1289.2857 | Q37: Ok | R37: Fri | S37: Weekday | T37: =VLOOKUP(Admissions[[#This Row],[Department]],Departments!A:E,5,FALSE) -> 6800 | U37: =IF(K37>T37,"Above Benchmark","Within Benchmark") -> Above Benchmark | V37: =INT(YEARFRAC(E37,TODAY())) -> 51 | W37: =_xlfn.IFS(Admissions[[#This Row],[Patients Age]]<18,"Paediatric",V37<40,"Young Adult",V37<65,"Adult",TRUE,"Senior") -> Adult
A38: 10497 | B38: Missing | C38: Barbara Gakuru | D38: Male | E38: 21439 | F38: Cardiology | G38: Dr. Patel | H38: 45555 | I38: 45559 | J38: 4 | K38: 11899 | L38: No | M38: I10 | N38: Private | O38: Valid | P38: 2974.75 | Q38: Ok | R38: Fri | S38: Weekday | T38: =VLOOKUP(Admissions[[#This Row],[Department]],Departments!A:E,5,FALSE) -> 8500 | U38: =IF(K38>T38,"Above Benchmark","Within Benchmark") -> Above Benchmark | V38: =INT(YEARFRAC(E38,TODAY())) -> 67 | W38: =_xlfn.IFS(Admissions[[#This Row],[Patients Age]]<18,"Paediatric",V38<40,"Young Adult",V38<65,"Adult",TRUE,"Senior") -> Senior
A39: 13221 | B39: 3732 | C39: Richard Juma | D39: Female | E39: 25381 | F39: Emergency | G39: Dr. Hassan | H39: 45646 | I39: 45649 | J39: 3 | K39: 6344 | L39: No | M39: A09 | N39: Public | O39: Valid | P39: 2114.6667 | Q39: Ok | R39: Fri | S39: Weekday | T39: =VLOOKUP(Admissions[[#This Row],[Department]],Departments!A:E,5,FALSE) -> 5500 | U39: =IF(K39>T39,"Above Benchmark","Within Benchmark") -> Above Benchmark | V39: =INT(YEARFRAC(E39,TODAY())) -> 57 | W39: =_xlfn.IFS(Admissions[[#This Row],[Patients Age]]<18,"Paediatric",V39<40,"Young Adult",V39<65,"Adult",TRUE,"Senior") -> Adult
A40: 13794 | B40: 7173 | C40: Joseph Wambua | D40: Male | E40: 36888 | F40: Emergency | G40: Dr. Hassan | H40: 45351 | I40: 45353 | J40: 2 | K40: 7262 | L40: No | M40: S72 | N40: Private | O40: Valid | P40: 3631 | Q40: Ok | R40: Thu | S40: Weekday | T40: =VLOOKUP(Admissions[[#This Row],[Department]],Departments!A:E,5,FALSE) -> 5500 | U40: =IF(K40>T40,"Above Benchmark","Within Benchmark") -> Above Benchmark | V40: =INT(YEARFRAC(E40,TODAY())) -> 25 | W40: =_xlfn.IFS(Admissions[[#This Row],[Patients Age]]<18,"Paediatric",V40<40,"Young Adult",V40<65,"Adult",TRUE,"Senior") -> Young Adult
A41: 10019 | B41: 6780 | C41: Fatuma Mwangi | D41: Female | E41: 24505 | F41: Neurology | G41: Dr. Andersen | H41: 45149 | I41: 45155 | J41: 6 | K41: 10172 | L41: No | M41: I63 | N41: Private | O41: Valid | P41: 1695.3333 | Q41: Ok | R41: Fri | S41: Weekday | T41: =VLOOKUP(Admissions[[#This Row],[Department]],Departments!A:E,5,FALSE) -> 7200 | U41: =IF(K41>T41,"Above Benchmark","Within Benchmark") -> Above Benchmark | V41: =INT(YEARFRAC(E41,TODAY())) -> 59 | W41: =_xlfn.IFS(Admissions[[#This Row],[Patients Age]]<18,"Paediatric",V41<40,"Young Adult",V41<65,"Adult",TRUE,"Senior") -> Adult
A42: 11378 | B42: 3871 | C42: Steven Kamau | D42: Female | E42: 14412 | F42: Emergency | G42: Dr. Hassan | H42: 45481 | I42: 45482 | J42: 1 | K42: 3777 | L42: No | M42: R51 | N42: Private | O42: Valid | P42: 3777 | Q42: Ok | R42: Mon | S42: Weekday | T42: =VLOOKUP(Admissions[[#This Row],[Department]],Departments!A:E,5,FALSE) -> 5500 | U42: =IF(K42>T42,"Above Benchmark","Within Benchmark") -> Within Benchmark | V42: =INT(YEARFRAC(E42,TODAY())) -> 87 | W42: =_xlfn.IFS(Admissions[[#This Row],[Patients Age]]<18,"Paediatric",V42<40,"Young Adult",V42<65,"Adult",TRUE,"Senior") -> Senior
A43: 15760 | B43: 6071 | C43: Mark Adhiambo | D43: Male | E43: 17457 | F43: Cardiology | G43: Dr. Kimani | H43: 45057 | I43: 45066 | J43: 9 | K43: 22599 | L43: No | M43: I21 | N43: Private | O43: Valid | P43: 2511 | Q43: Ok | R43: Thu | S43: Weekday | T43: =VLOOKUP(Admissions[[#This Row],[Department]],Departments!A:E,5,FALSE) -> 8500 | U43: =IF(K43>T43,"Above Benchmark","Within Benchmark") -> Above Benchmark | V43: =INT(YEARFRAC(E43,TODAY())) -> 78 | W43: =_xlfn.IFS(Admissions[[#This Row],[Patients Age]]<18,"Paediatric",V43<40,"Young Adult",V43<65,"Adult",TRUE,"Senior") -> Senior
A44: 14143 | B44: 6517 | C44: Patricia Korir | D44: Female | E44: 27071 | F44: Surgery | G44: Dr. Chen | H44: 45304 | I44: 45312 | J44: 8 | K44: 15693 | L44: No | M44: K35 | N44: Public | O44: Valid | P44: 1961.625 | Q44: Ok | R44: Sat | S44: Weekend | T44: =VLOOKUP(Admissions[[#This Row],[Department]],Departments!A:E,5,FALSE) -> 9000 | U44: =IF(K44>T44,"Above Benchmark","Within Benchmark") -> Above Benchmark | V44: =INT(YEARFRAC(E44,TODAY())) -> 52 | W44: =_xlfn.IFS(Admissions[[#This Row],[Patients Age]]<18,"Paediatric",V44<40,"Young Adult",V44<65,"Adult",TRUE,"Senior") -> Adult
A45: 10470 | B45: 4511 | C45: William Abdi | D45: Female | E45: 27944 | F45: Cardiology | G45: Dr. Kimani | H45: 45429 | I45: 45433 | J45: 4 | K45: 10795 | L45: No | M45: I21 | N45: Private | O45: Valid | P45: 2698.75 | Q45: Ok | R45: Fri | S45: Weekday | T45: =VLOOKUP(Admissions[[#This Row],[Department]],Departments!A:E,5,FALSE) -> 8500 | U45: =IF(K45>T45,"Above Benchmark","Within Benchmark") -> Above Benchmark | V45: =INT(YEARFRAC(E45,TODAY())) -> 50 | W45: =_xlfn.IFS(Admissions[[#This Row],[Patients Age]]<18,"Paediatric",V45<40,"Young Adult",V45<65,"Adult",TRUE,"Senior") -> Adult
A46: 13189 | B46: 4544 | C46: John Gakuru | D46: Male | E46: 22552 | F46: Orthopedics | G46: Dr. Svensson | H46: 45399 | I46: 45407 | J46: 8 | K46: 9676 | L46: No | M46: M17 | N46: Private | O46: Valid | P46: 1209.5 | Q46: Ok | R46: Wed | S46: Weekday | T46: =VLOOKUP(Admissions[[#This Row],[Department]],Departments!A:E,5,FALSE) -> 6800 | U46: =IF(K46>T46,"Above Benchmark","Within Benchmark") -> Above Benchmark | V46: =INT(YEARFRAC(E46,TODAY())) -> 64 | W46: =_xlfn.IFS(Admissions[[#This Row],[Patients Age]]<18,"Paediatric",V46<40,"Young Adult",V46<65,"Adult",TRUE,"Senior") -> Adult
A47: 14120 | B47: 6463 | C47: Karen Lagat | D47: Male | E47: 30670 | F47: Cardiology | G47: Dr. Torres | H47: 45480 | I47: 45482 | J47: 2 | K47: 4902 | L47: No | M47: I48 | N47: Public | O47: Valid | P47: 2451 | Q47: Ok | R47: Sun | S47: Weekend | T47: =VLOOKUP(Admissions[[#This Row],[Department]],Departments!A:E,5,FALSE) -> 8500 | U47: =IF(K47>T47,"Above Benchmark","Within Benchmark") -> Within Benchmark | V47: =INT(YEARFRAC(E47,TODAY())) -> 42 | W47: =_xlfn.IFS(Admissions[[#This Row],[Patients Age]]<18,"Paediatric",V47<40,"Young Adult",V47<65,"Adult",TRUE,"Senior") -> Adult
A48: 14268 | B48: 4550 | C48: Christopher Njenga | D48: Female | E48: 44548 | F48: Pediatrics | G48: Dr. Chebet | H48: 44945 | I48: 44949 | J48: 4 | K48: 4591 | L48: No | M48: A09 | N48: Public | O48: Valid | P48: 1147.75 | Q48: Ok | R48: Thu | S48: Weekday | T48: =VLOOKUP(Admissions[[#This Row],[Department]],Departments!A:E,5,FALSE) -> 4500 | U48: =IF(K48>T48,"Above Benchmark","Within Benchmark") -> Above Benchmark | V48: =INT(YEARFRAC(E48,TODAY())) -> 4 | W48: =_xlfn.IFS(Admissions[[#This Row],[Patients Age]]<18,"Paediatric",V48<40,"Young Adult",V48<65,"Adult",TRUE,"Senior") -> Paediatric
A49: 15252 | B49: 5971 | C49: Ruth Mutua | D49: Male | E49: 29350 | F49: Neurology | G49: Dr. Abdi | H49: 45095 | I49: 45101 | J49: 6 | K49: 9164 | L49: No | M49: I63 | N49: Uninsured | O49: Valid | P49: 1527.3333 | Q49: Ok | R49: Sun | S49: Weekend | T49: =VLOOKUP(Admissions[[#This Row],[Department]],Departments!A:E,5,FALSE) -> 7200 | U49: =IF(K49>T49,"Above Benchmark","Within Benchmark") -> Above Benchmark | V49: =INT(YEARFRAC(E49,TODAY())) -> 46 | W49: =_xlfn.IFS(Admissions[[#This Row],[Patients Age]]<18,"Paediatric",V49<40,"Young Adult",V49<65,"Adult",TRUE,"Senior") -> Adult
A50: 13845 | B50: 7073 | C50: Emily Mbugua | D50: Female | E50: 20900 | F50: Orthopedics | G50: Dr. Mwangi | H50: 44970 | I50: 44981 | J50: 11 | K50: 15725 | L50: No | M50: M16 | N50: Public | O50: Valid | P50: 1429.5455 | Q50: Ok | R50: Mon | S50: Weekday | T50: =VLOOKUP(Admissions[[#This Row],[Department]],Departments!A:E,5,FALSE) -> 6800 | U50: =IF(K50>T50,"Above Benchmark","Within Benchmark") -> Above Benchmark | V50: =INT(YEARFRAC(E50,TODAY())) -> 69 | W50: =_xlfn.IFS(Admissions[[#This Row],[Patients Age]]<18,"Paediatric",V50<40,"Young Adult",V50<65,"Adult",TRUE,"Senior") -> Senior
... A135: 14826 | B135: 5316 | C135: Paul Achieng | D135: Female | E135: 29830 | F135: Cardiology | G135: Dr. Kimani | H135: 45138 | I135: 45144 | J135: 6 | K135: 11845 | L135: No | M135: I21 | N135: Public | O135: Valid | P135: 1974.1667 | Q135: Ok | R135: Mon | S135: Weekday | T135: =VLOOKUP(Admissions[[#This Row],[Department]],Departments!A:E,5,FALSE) -> 8500 | U135: =IF(K135>T135,"Above Benchmark","Within Benchmark") -> Above Benchmark | V135: =INT(YEARFRAC(E135,TODAY())) -> 44 | W135: =_xlfn.IFS(Admissions[[#This Row],[Patients Age]]<18,"Paediatric",V135<40,"Young Adult",V135<65,"Adult",TRUE,"Senior") -> Adult
A136: 11828 | B136: Missing | C136: Helen Kariuki | D136: Male | E136: 14261 | F136: Cardiology | G136: Dr. Patel | H136: 45262 | I136: 45268 | J136: 6 | K136: 16332 | L136: No | M136: I10 | N136: Uninsured | O136: Valid | P136: 2722 | Q136: Ok | R136: Sat | S136: Weekend | T136: =VLOOKUP(Admissions[[#This Row],[Department]],Departments!A:E,5,FALSE) -> 8500 | U136: =IF(K136>T136,"Above Benchmark","Within Benchmark") -> Above Benchmark | V136: =INT(YEARFRAC(E136,TODAY())) -> 87 | W136: =_xlfn.IFS(Admissions[[#This Row],[Patients Age]]<18,"Paediatric",V136<40,"Young Adult",V136<65,"Adult",TRUE,"Senior") -> Senior
A137: 11090 | B137: 3533 | C137: James Githinji | D137: Male | E137: 31189 | F137: Surgery | G137: Dr. Chen | H137: 45129 | I137: 45135 | J137: 6 | K137: 11863 | L137: No | M137: S72 | N137: Private | O137: Valid | P137: 1977.1667 | Q137: Ok | R137: Sat | S137: Weekend | T137: =VLOOKUP(Admissions[[#This Row],[Department]],Departments!A:E,5,FALSE) -> 9000 | U137: =IF(K137>T137,"Above Benchmark","Within Benchmark") -> Above Benchmark | V137: =INT(YEARFRAC(E137,TODAY())) -> 41 | W137: =_xlfn.IFS(Admissions[[#This Row],[Patients Age]]<18,"Paediatric",V137<40,"Young Adult",V137<65,"Adult",TRUE,"Senior") -> Adult
A138: 10828 | B138: 6435 | C138: John Otieno | D138: Male | E138: 32233 | F138: Emergency | G138: Dr. Hassan | H138: 45104 | I138: 45105 | J138: 1 | K138: 3140 | L138: No | M138: A09 | N138: Public | O138: Valid | P138: 3140 | Q138: Ok | R138: Tue | S138: Weekday | T138: =VLOOKUP(Admissions[[#This Row],[Department]],Departments!A:E,5,FALSE) -> 5500 | U138: =IF(K138>T138,"Above Benchmark","Within Benchmark") -> Within Benchmark | V138: =INT(YEARFRAC(E138,TODAY())) -> 38 | W138: =_xlfn.IFS(Admissions[[#This Row],[Patients Age]]<18,"Paediatric",V138<40,"Young Adult",V138<65,"Adult",TRUE,"Senior") -> Young Adult
A139: 10316 | B139: 7188 | C139: Michael Omondi | D139: Male | E139: 38507 | F139: Cardiology | G139: Dr. Patel | H139: 45301 | I139: 45308 | J139: 7 | K139: 10693 | L139: No | M139: I21 | N139: Uninsured | O139: Valid | P139: 1527.5714 | Q139: Ok | R139: Wed | S139: Weekday | T139: =VLOOKUP(Admissions[[#This Row],[Department]],Departments!A:E,5,FALSE) -> 8500 | U139: =IF(K139>T139,"Above Benchmark","Within Benchmark") -> Above Benchmark | V139: =INT(YEARFRAC(E139,TODAY())) -> 21 | W139: =_xlfn.IFS(Admissions[[#This Row],[Patients Age]]<18,"Paediatric",V139<40,"Young Adult",V139<65,"Adult",TRUE,"Senior") -> Young Adult
A140: 13441 | B140: 5469 | C140: Patricia Kimani | D140: Male | E140: 26806 | F140: Orthopedics | G140: Dr. Mwangi | H140: 45623 | I140: 45629 | J140: 6 | K140: 4718 | L140: Yes | M140: M54 | N140: Public | O140: Valid | P140: 786.3333 | Q140: Ok | R140: Wed | S140: Weekday | T140: =VLOOKUP(Admissions[[#This Row],[Department]],Departments!A:E,5,FALSE) -> 6800 | U140: =IF(K140>T140,"Above Benchmark","Within Benchmark") -> Within Benchmark | V140: =INT(YEARFRAC(E140,TODAY())) -> 53 | W140: =_xlfn.IFS(Admissions[[#This Row],[Patients Age]]<18,"Paediatric",V140<40,"Young Adult",V140<65,"Adult",TRUE,"Senior") -> Adult
A141: 10900 | B141: 4573 | C141: Betty Mugo | D141: Female | E141: 29532 | F141: Internal Medicine | G141: Dr. Nair | H141: 45122 | I141: 45126 | J141: 4 | K141: 5048 | L141: No | M141: J44 | N141: Public | O141: Valid | P141: 1262 | Q141: Ok | R141: Sat | S141: Weekend | T141: =VLOOKUP(Admissions[[#This Row],[Department]],Departments!A:E,5,FALSE) -> 6000 | U141: =IF(K141>T141,"Above Benchmark","Within Benchmark") -> Within Benchmark | V141: =INT(YEARFRAC(E141,TODAY())) -> 45 | W141: =_xlfn.IFS(Admissions[[#This Row],[Patients Age]]<18,"Paediatric",V141<40,"Young Adult",V141<65,"Adult",TRUE,"Senior") -> Adult
A142: 15840 | B142: 3121 | C142: Linda Mohammed | D142: Male | E142: 18335 | F142: Orthopedics | G142: Dr. Svensson | H142: 45426 | I142: 45430 | J142: 4 | K142: 7152 | L142: No | M142: M54 | N142: Private | O142: Valid | P142: 1788 | Q142: Ok | R142: Tue | S142: Weekday | T142: =VLOOKUP(Admissions[[#This Row],[Department]],Departments!A:E,5,FALSE) -> 6800 | U142: =IF(K142>T142,"Above Benchmark","Within Benchmark") -> Above Benchmark | V142: =INT(YEARFRAC(E142,TODAY())) -> 76 | W142: =_xlfn.IFS(Admissions[[#This Row],[Patients Age]]<18,"Paediatric",V142<40,"Young Adult",V142<65,"Adult",TRUE,"Senior") -> Senior
A143: 11975 | B143: 6326 | C143: Grace Kimani | D143: Male | E143: 27392 | F143: Oncology | G143: Dr. Ruto | H143: 45630 | I143: 45637 | J143: 7 | K143: 27307 | L143: No | M143: C50 | N143: Public | O143: Valid | P143: 3901 | Q143: Ok | R143: Wed | S143: Weekday | T143: =VLOOKUP(Admissions[[#This Row],[Department]],Departments!A:E,5,FALSE) -> 12000 | U143: =IF(K143>T143,"Above Benchmark","Within Benchmark") -> Above Benchmark | V143: =INT(YEARFRAC(E143,TODAY())) -> 51 | W143: =_xlfn.IFS(Admissions[[#This Row],[Patients Age]]<18,"Paediatric",V143<40,"Young Adult",V143<65,"Adult",TRUE,"Senior") -> Adult
A144: 10260 | B144: 6303 | C144: Grace Chesang | D144: Female | E144: 35649 | F144: Internal Medicine | G144: Dr. Githinji | H144: 45412 | I144: 45416 | J144: 4 | K144: 6263 | L144: No | M144: N18 | N144: Public | O144: Valid | P144: 1565.75 | Q144: Ok | R144: Tue | S144: Weekday | T144: =VLOOKUP(Admissions[[#This Row],[Department]],Departments!A:E,5,FALSE) -> 6000 | U144: =IF(K144>T144,"Above Benchmark","Within Benchmark") -> Above Benchmark | V144: =INT(YEARFRAC(E144,TODAY())) -> 28 | W144: =_xlfn.IFS(Admissions[[#This Row],[Patients Age]]<18,"Paediatric",V144<40,"Young Adult",V144<65,"Adult",TRUE,"Senior") -> Young Adult
A145: 10153 | B145: 6157 | C145: Ruth Mohammed | D145: Female | E145: 14067 | F145: Orthopedics | G145: Dr. Mwangi | H145: 45382 | I145: 45384 | J145: 2 | K145: 6538 | L145: No | M145: S72 | N145: Private | O145: Valid | P145: 3269 | Q145: Ok | R145: Sun | S145: Weekend | T145: =VLOOKUP(Admissions[[#This Row],[Department]],Departments!A:E,5,FALSE) -> 6800 | U145: =IF(K145>T145,"Above Benchmark","Within Benchmark") -> Within Benchmark | V145: =INT(YEARFRAC(E145,TODAY())) -> 88 | W145: =_xlfn.IFS(Admissions[[#This Row],[Patients Age]]<18,"Paediatric",V145<40,"Young Adult",V145<65,"Adult",TRUE,"Senior") -> Senior
A146: 14270 | B146: 4719 | C146: Anthony Achieng | D146: Male | E146: 20543 | F146: Neurology | G146: Dr. Abdi | H146: 45500 | I146: 45505 | J146: 5 | K146: 7618 | L146: No | M146: R51 | N146: Private | O146: Valid | P146: 1523.6 | Q146: Ok | R146: Sat | S146: Weekend | T146: =VLOOKUP(Admissions[[#This Row],[Department]],Departments!A:E,5,FALSE) -> 7200 | U146: =IF(K146>T146,"Above Benchmark","Within Benchmark") -> Above Benchmark | V146: =INT(YEARFRAC(E146,TODAY())) -> 70 | W146: =_xlfn.IFS(Admissions[[#This Row],[Patients Age]]<18,"Paediatric",V146<40,"Young Adult",V146<65,"Adult",TRUE,"Senior") -> Senior
A147: 13628 | B147: 3030 | C147: Joshua Wanjiku | D147: Female | E147: 30831 | F147: Oncology | G147: Dr. Osei | H147: 45581 | I147: 45586 | J147: 5 | K147: 13691 | L147: No | M147: C61 | N147: Public | O147: Valid | P147: 2738.2 | Q147: Ok | R147: Wed | S147: Weekday | T147: =VLOOKUP(Admissions[[#This Row],[Department]],Departments!A:E,5,FALSE) -> 12000 | U147: =IF(K147>T147,"Above Benchmark","Within Benchmark") -> Above Benchmark | V147: =INT(YEARFRAC(E147,TODAY())) -> 42 | W147: =_xlfn.IFS(Admissions[[#This Row],[Patients Age]]<18,"Paediatric",V147<40,"Young Adult",V147<65,"Adult",TRUE,"Senior") -> Adult
...

Sheet Departments
A1: Department_Name | B1: Dept_ID | C1: Department_Type | D1: Head_Doctor | E1: Cost_Benchmark
A2: Cardiology | B2: 1 | C2: Inpatient | D2: Dr. Patel | E2: 8500
A3: Emergency | B3: 2 | C3: Emergency | D3: Dr. Hassan | E3: 5500
A4: Surgery | B4: 3 | C4: Inpatient | D4: Dr. Chen | E4: 9000
A5: Oncology | B5: 4 | C5: Inpatient | D5: Dr. Osei | E5: 12000
A6: Neurology | B6: 5 | C6: Inpatient | D6: Dr. Andersen | E6: 7200
A7: Orthopedics | B7: 6 | C7: Inpatient | D7: Dr. Mwangi | E7: 6800
A8: Pediatrics | B8: 7 | C8: Outpatient | D8: Dr. Korir | E8: 4500
A9: Internal Medicine | B9: 8 | C9: Outpatient | D9: Dr. Nair | E9: 6000

Sheet Analysis
A1: Total Admissions | B1: Average LOS | C1: Total Cost | D1: Cost Per Patient | E1: Total Readmissions | F1: Readmission % | J1: Department_Name | K1: Total Cost | L1: Average LOS | P1: Department_Name | Q1: Readmission % | S1: Department_Name | T1: Readmission %
A2: 366 | B2: 5.5191257 | C2: 2922959 | D2: 7986.2268 | E2: 33 | F2: 0.090163934 | J2: Cardiology | K2: 8078433 | L2: 5.7863105 | P2: Cardiology | Q2: 0.1903172 | S2: =INDEX($P$2:$P$9,MATCH(T2,$Q$2:$Q$9,0)) -> Cardiology | T2: =LARGE($Q$2:$Q$9,ROWS(F$2:F2)) -> 0.1903172
J3: Emergency | K3: 3326011 | L3: 2.4452555 | P3: Emergency | Q3: 0.14233577 | S3: =INDEX($P$2:$P$9,MATCH(T3,$Q$2:$Q$9,0)) -> Emergency | T3: =LARGE($Q$2:$Q$9,ROWS(F$2:F3)) -> 0.14233577
J4: Internal Medicine | K4: 3280914 | L4: 4.1616766 | P4: Internal Medicine | Q4: 0.080838323 | S4: =INDEX($P$2:$P$9,MATCH(T4,$Q$2:$Q$9,0)) -> Oncology | T4: =LARGE($Q$2:$Q$9,ROWS(F$2:F4)) -> 0.095808383
J5: Neurology | K5: 2446024 | L5: 5.0169492 | P5: Neurology | Q5: 0.084745763 | S5: =INDEX($P$2:$P$9,MATCH(T5,$Q$2:$Q$9,0)) -> Surgery | T5: =LARGE($Q$2:$Q$9,ROWS(F$2:F5)) -> 0.094567404
J6: Oncology | K6: 8927680 | L6: 8.0209581 | P6: Oncology | Q6: 0.095808383 | S6: =INDEX($P$2:$P$9,MATCH(T6,$Q$2:$Q$9,0)) -> Orthopedics | T6: =LARGE($Q$2:$Q$9,ROWS(F$2:F6)) -> 0.090163934
J7: Orthopedics | K7: 2922959 | L7: 5.5191257 | P7: Orthopedics | Q7: 0.090163934
A8: Department_Name | B8: Readmission % | J8: Pediatrics | K8: 2816203 | L8: 2.8096886 | P8: Pediatrics | Q8: 0.076124567
A9: Pediatrics | B9: 0.076124567 | J9: Surgery | K9: 9339917 | L9: 6.8853119 | P9: Surgery | Q9: 0.094567404
A10: Internal Medicine | B10: 0.080838323
A11: Neurology | B11: 0.084745763
A12: Orthopedics | B12: 0.090163934 | J12: Department_Type | K12: Total Admissions | P12: DATE | Q12: =TODAY() -> 46211
A13: Surgery | B13: 0.094567404 | J13: Emergency | K13: 548
A14: Oncology | B14: 0.095808383 | J14: Inpatient | K14: 2091
A15: Emergency | B15: 0.14233577 | J15: Outpatient | K15: 623
A16: Cardiology | B16: 0.1903172
A20: Month Name | B20: Total Admissions
A21: Jan | B21: 32
A22: Feb | B22: 25
A23: Mar | B23: 31
A24: Apr | B24: 33
A25: May | B25: 25
A26: Jun | B26: 36
A27: Jul | B27: 25
A28: Sep | B28: 32
A29: Oct | B29: 48
A30: Nov | B30: 48
A31: Dec | B31: 31

Sheet Dashboard
P24: Department name | Q24: Readmission %
P25: =Analysis!S2 -> Cardiology | Q25: =Analysis!T2 -> 0.1903172
P26: =Analysis!S3 -> Emergency | Q26: =Analysis!T3 -> 0.14233577
P27: =Analysis!S4 -> Oncology | Q27: =Analysis!T4 -> 0.095808383
P28: =Analysis!S5 -> Surgery | Q28: =Analysis!T5 -> 0.094567404
P29: =Analysis!S6 -> Orthopedics | Q29: =Analysis!T6 -> 0.090163934
